/*
  知识点：
  1、可见 co(function *(){ ... }) 是一段自执行代码，没有参数传入
    要定义 co 函数，通过  co.wrap(fn*) 
  2、co 必须自己配 catch，才能看到错误信息


*/
var co = require('co');

co(function *(){
  // yield any promise
  var result = yield Promise.resolve(true);
}).catch(onerror);

co(function *(){
  // resolve multiple promises in parallel
  var a = Promise.resolve(1);
  var b = Promise.resolve(2);
  var c = Promise.resolve(3);
  var res = yield [a, b, c];
  console.log(res);
  // => [1, 2, 3]
}).catch(onerror);

// errors can be try/catched
co(function *(){
  try {
    yield Promise.reject(new Error('boom'));
  } catch (err) {
    console.error(err.message); // "boom"
 }
}).catch(onerror);

function onerror(err) {
  // log any uncaught errors
  // co will not throw any errors you do not handle!!!
  // HANDLE ALL YOUR ERRORS!!!
  console.error(err.stack);
}
